Workbook

Sheet Data
A1: Order ID | B1: Order Date | C1: Customer ID | D1: Segment | E1: Region | F1: State | G1: Category | H1: Product | I1: Quantity | J1: Unit Price | K1: Discount % | L1: Sales | M1: Unit Cost | N1: Profit | O1: Payment Method | P1: Sales Rep | Q1: Rating | R1: month | S1: month no | T1: profit/loss | U1: order size | V1: profit margin
A2: ORD-10001 | B2: 45658 | C2: CUST-0384 | D2: Small Business | E2: North | F2: Delhi | G2: Clothing | H2: Jeans | I2: 1 | J2: 84.05 | K2: 0 | L2: =I2*J2*(1-K2) -> 84.05 | M2: 37.26 | N2: =L2-I2*M2 -> 46.79 | O2: UPI | P2: Meera Reddy | Q2: 3 | R2: =TEXT(Table1[[#This Row],[Order Date]],"mmm") -> Jan | S2: =TEXT(Table1[[#This Row],[Order Date]],"mm") -> 01 | T2: =IF(Table1[[#This Row],[Sales]]<0,"loss","profit") -> profit | U2: {=_xlfn.IFS(Table1[[#This Row],[Sales]]>2000,"large",Table1[[#This Row],[Sales]]>=500,"medium",Table1[[#This Row],[Sales]]<500,"small")} -> small | V2: =Table1[[#This Row],[Profit]]/Table1[[#This Row],[Sales]]*100 -> 55.669244
A3: ORD-10002 | B3: 45658 | C3: CUST-0222 | D3: Small Business | E3: West | F3: Gujarat | G3: Home & Kitchen | H3: Vacuum Cleaner | I3: 1 | J3: 381.08 | K3: 0 | L3: =I3*J3*(1-K3) -> 381.08 | M3: 247.67 | N3: =L3-I3*M3 -> 133.41 | O3: UPI | P3: Vikram Singh | Q3: 1 | R3: =TEXT(Table1[[#This Row],[Order Date]],"mmm") -> Jan | S3: =TEXT(Table1[[#This Row],[Order Date]],"mm") -> 01 | T3: =IF(Table1[[#This Row],[Sales]]<0,"loss","profit") -> profit | U3: {=_xlfn.IFS(Table1[[#This Row],[Sales]]>2000,"large",Table1[[#This Row],[Sales]]>=500,"medium",Table1[[#This Row],[Sales]]<500,"small")} -> small | V3: =Table1[[#This Row],[Profit]]/Table1[[#This Row],[Sales]]*100 -> 35.008397
A4: ORD-10003 | B4: 45658 | C4: CUST-0241 | D4: Small Business | E4: East | F4: Bihar | G4: Electronics | H4: Smartwatch | I4: 1 | J4: 297.24 | K4: 0.1 | L4: =I4*J4*(1-K4) -> 267.516 | M4: 266.59 | N4: =L4-I4*M4 -> 0.926 | O4: Cash | P4: Vikram Singh | Q4: 3 | R4: =TEXT(Table1[[#This Row],[Order Date]],"mmm") -> Jan | S4: =TEXT(Table1[[#This Row],[Order Date]],"mm") -> 01 | T4: =IF(Table1[[#This Row],[Sales]]<0,"loss","profit") -> profit | U4: {=_xlfn.IFS(Table1[[#This Row],[Sales]]>2000,"large",Table1[[#This Row],[Sales]]>=500,"medium",Table1[[#This Row],[Sales]]<500,"small")} -> small | V4: =Table1[[#This Row],[Profit]]/Table1[[#This Row],[Sales]]*100 -> 0.34614752
A5: ORD-10004 | B5: 45659 | C5: CUST-0083 | D5: Corporate | E5: West | F5: Gujarat | G5: Clothing | H5: Sneakers | I5: 2 | J5: 156.29 | K5: 0 | L5: =I5*J5*(1-K5) -> 312.58 | M5: 83.22 | N5: =L5-I5*M5 -> 146.14 | O5: Cash | P5: Meera Reddy | Q5: 3 | R5: =TEXT(Table1[[#This Row],[Order Date]],"mmm") -> Jan | S5: =TEXT(Table1[[#This Row],[Order Date]],"mm") -> 01 | T5: =IF(Table1[[#This Row],[Sales]]<0,"loss","profit") -> profit | U5: {=_xlfn.IFS(Table1[[#This Row],[Sales]]>2000,"large",Table1[[#This Row],[Sales]]>=500,"medium",Table1[[#This Row],[Sales]]<500,"small")} -> small | V5: =Table1[[#This Row],[Profit]]/Table1[[#This Row],[Sales]]*100 -> 46.752831
A6: ORD-10005 | B6: 45659 | C6: CUST-0264 | D6: Consumer | E6: East | F6: West Bengal | G6: Sports | H6: Yoga Mat | I6: 10 | J6: 29.28 | K6: 0.05 | L6: =I6*J6*(1-K6) -> 278.16 | M6: 20.12 | N6: =L6-I6*M6 -> 76.96 | O6: Net Banking | P6: Meera Reddy | Q6: 4 | R6: =TEXT(Table1[[#This Row],[Order Date]],"mmm") -> Jan | S6: =TEXT(Table1[[#This Row],[Order Date]],"mm") -> 01 | T6: =IF(Table1[[#This Row],[Sales]]<0,"loss","profit") -> profit | U6: {=_xlfn.IFS(Table1[[#This Row],[Sales]]>2000,"large",Table1[[#This Row],[Sales]]>=500,"medium",Table1[[#This Row],[Sales]]<500,"small")} -> small | V6: =Table1[[#This Row],[Profit]]/Table1[[#This Row],[Sales]]*100 -> 27.667529
A7: ORD-10006 | B7: 45659 | C7: CUST-0148 | D7: Corporate | E7: West | F7: Maharashtra | G7: Electronics | H7: Headphones | I7: 1 | J7: 198.11 | K7: 0.05 | L7: =I7*J7*(1-K7) -> 188.2045 | M7: 163.49 | N7: =L7-I7*M7 -> 24.7145 | O7: Cash | P7: Priya Nair | Q7: 1 | R7: =TEXT(Table1[[#This Row],[Order Date]],"mmm") -> Jan | S7: =TEXT(Table1[[#This Row],[Order Date]],"mm") -> 01 | T7: =IF(Table1[[#This Row],[Sales]]<0,"loss","profit") -> profit | U7: {=_xlfn.IFS(Table1[[#This Row],[Sales]]>2000,"large",Table1[[#This Row],[Sales]]>=500,"medium",Table1[[#This Row],[Sales]]<500,"small")} -> small | V7: =Table1[[#This Row],[Profit]]/Table1[[#This Row],[Sales]]*100 -> 13.131726
A8: ORD-10007 | B8: 45659 | C8: CUST-0059 | D8: Corporate | E8: North | F8: Haryana | G8: Clothing | H8: Jeans | I8: 2 | J8: 71.14 | K8: 0 | L8: =I8*J8*(1-K8) -> 142.28 | M8: 40.71 | N8: =L8-I8*M8 -> 60.86 | O8: Credit Card | P8: Rohan Mehta | Q8: 4 | R8: =TEXT(Table1[[#This Row],[Order Date]],"mmm") -> Jan | S8: =TEXT(Table1[[#This Row],[Order Date]],"mm") -> 01 | T8: =IF(Table1[[#This Row],[Sales]]<0,"loss","profit") -> profit | U8: {=_xlfn.IFS(Table1[[#This Row],[Sales]]>2000,"large",Table1[[#This Row],[Sales]]>=500,"medium",Table1[[#This Row],[Sales]]<500,"small")} -> small | V8: =Table1[[#This Row],[Profit]]/Table1[[#This Row],[Sales]]*100 -> 42.77481
A9: ORD-10008 | B9: 45660 | C9: CUST-0098 | D9: Small Business | E9: West | F9: Maharashtra | G9: Home & Kitchen | H9: Cookware Set | I9: 2 | J9: 127.25 | K9: 0 | L9: =I9*J9*(1-K9) -> 254.5 | M9: 83.16 | N9: =L9-I9*M9 -> 88.18 | O9: Net Banking | P9: Rohan Mehta | Q9: 5 | R9: =TEXT(Table1[[#This Row],[Order Date]],"mmm") -> Jan | S9: =TEXT(Table1[[#This Row],[Order Date]],"mm") -> 01 | T9: =IF(Table1[[#This Row],[Sales]]<0,"loss","profit") -> profit | U9: {=_xlfn.IFS(Table1[[#This Row],[Sales]]>2000,"large",Table1[[#This Row],[Sales]]>=500,"medium",Table1[[#This Row],[Sales]]<500,"small")} -> small | V9: =Table1[[#This Row],[Profit]]/Table1[[#This Row],[Sales]]*100 -> 34.64833
A10: ORD-10009 | B10: 45661 | C10: CUST-0301 | D10: Small Business | E10: East | F10: West Bengal | G10: Furniture | H10: Sofa | I10: 1 | J10: 605.89 | K10: 0 | L10: =I10*J10*(1-K10) -> 605.89 | M10: 389.26 | N10: =L10-I10*M10 -> 216.63 | O10: Cash | P10: Rohan Mehta | Q10: 4 | R10: =TEXT(Table1[[#This Row],[Order Date]],"mmm") -> Jan | S10: =TEXT(Table1[[#This Row],[Order Date]],"mm") -> 01 | T10: =IF(Table1[[#This Row],[Sales]]<0,"loss","profit") -> profit | U10: {=_xlfn.IFS(Table1[[#This Row],[Sales]]>2000,"large",Table1[[#This Row],[Sales]]>=500,"medium",Table1[[#This Row],[Sales]]<500,"small")} -> medium | V10: =Table1[[#This Row],[Profit]]/Table1[[#This Row],[Sales]]*100 -> 35.754015
A11: ORD-10010 | B11: 45661 | C11: CUST-0123 | D11: Small Business | E11: West | F11: Gujarat | G11: Clothing | H11: Jacket | I11: 5 | J11: 141.59 | K11: 0.2 | L11: =I11*J11*(1-K11) -> 566.36 | M11: 72.8 | N11: =L11-I11*M11 -> 202.36 | O11: Cash | P11: Sneha Iyer | Q11: 5 | R11: =TEXT(Table1[[#This Row],[Order Date]],"mmm") -> Jan | S11: =TEXT(Table1[[#This Row],[Order Date]],"mm") -> 01 | T11: =IF(Table1[[#This Row],[Sales]]<0,"loss","profit") -> profit | U11: {=_xlfn.IFS(Table1[[#This Row],[Sales]]>2000,"large",Table1[[#This Row],[Sales]]>=500,"medium",Table1[[#This Row],[Sales]]<500,"small")} -> medium | V11: =Table1[[#This Row],[Profit]]/Table1[[#This Row],[Sales]]*100 -> 35.729924
A12: ORD-10011 | B12: 45661 | C12: CUST-0334 | D12: Consumer | E12: West | F12: Gujarat | G12: Clothing | H12: Jacket | I12: 10 | J12: 175.32 | K12: 0.1 | L12: =I12*J12*(1-K12) -> 1577.88 | M12: 83.05 | N12: =L12-I12*M12 -> 747.38 | O12: Cash | P12: Aarav Sharma | Q12: 3 | R12: =TEXT(Table1[[#This Row],[Order Date]],"mmm") -> Jan | S12: =TEXT(Table1[[#This Row],[Order Date]],"mm") -> 01 | T12: =IF(Table1[[#This Row],[Sales]]<0,"loss","profit") -> profit | U12: {=_xlfn.IFS(Table1[[#This Row],[Sales]]>2000,"large",Table1[[#This Row],[Sales]]>=500,"medium",Table1[[#This Row],[Sales]]<500,"small")} -> medium | V12: =Table1[[#This Row],[Profit]]/Table1[[#This Row],[Sales]]*100 -> 47.366086
A13: ORD-10012 | B13: 45662 | C13: CUST-0370 | D13: Consumer | E13: West | F13: Maharashtra | G13: Sports | H13: Bicycle | I13: 2 | J13: 715.31 | K13: 0.05 | L13: =I13*J13*(1-K13) -> 1359.089 | M13: 411.42 | N13: =L13-I13*M13 -> 536.249 | O13: Cash | P13: Rohan Mehta | Q13: 2 | R13: =TEXT(Table1[[#This Row],[Order Date]],"mmm") -> Jan | S13: =TEXT(Table1[[#This Row],[Order Date]],"mm") -> 01 | T13: =IF(Table1[[#This Row],[Sales]]<0,"loss","profit") -> profit | U13: {=_xlfn.IFS(Table1[[#This Row],[Sales]]>2000,"large",Table1[[#This Row],[Sales]]>=500,"medium",Table1[[#This Row],[Sales]]<500,"small")} -> medium | V13: =Table1[[#This Row],[Profit]]/Table1[[#This Row],[Sales]]*100 -> 39.456504
... A1001: ORD-11000 | B1001: 46022 | C1001: CUST-0140 | D1001: Corporate | E1001: East | F1001: West Bengal | G1001: Electronics | H1001: Headphones | I1001: 8 | J1001: 268.13 | K1001: 0.1 | L1001: =I1001*J1001*(1-K1001) -> 1930.536 | M1001: 224.31 | N1001: =L1001-I1001*M1001 -> 136.056 | O1001: Credit Card | P1001: Karan Patel | Q1001: 5 | R1001: =TEXT(Table1[[#This Row],[Order Date]],"mmm") -> Dec | S1001: =TEXT(Table1[[#This Row],[Order Date]],"mm") -> 12 | T1001: =IF(Table1[[#This Row],[Sales]]<0,"loss","profit") -> profit | U1001: {=_xlfn.IFS(Table1[[#This Row],[Sales]]>2000,"large",Table1[[#This Row],[Sales]]>=500,"medium",Table1[[#This Row],[Sales]]<500,"small")} -> medium | V1001: =Table1[[#This Row],[Profit]]/Table1[[#This Row],[Sales]]*100 -> 7.0475764

Sheet Analysis
A1: Sales Analysis
A3: KPIs
A4: Total Sales | B4: =SUM(Data!L2:L1001) -> 692809.63
A5: Total Profit | B5: =SUM(Data!N2:N1001) -> 146599.95
A6: Profit Margin | B6: =B5/B4 -> 0.21160207
A7: Total Orders | B7: =COUNTA(Data!A2:A1001) -> 1000
A8: Avg Order Value | B8: =B4/B7 -> 692.80963
A9: Avg Rating | B9: =AVERAGE(Data!Q2:Q1001) -> 3.839
A12: Sales by Region
A13: Region | B13: Sales | C13: Profit | D13: Orders | E13: Margin
A14: North | B14: =SUMIFS(Data!$L$2:$L$1001,Data!$E$2:$E$1001,A14) -> 169068.16 | C14: =SUMIFS(Data!$N$2:$N$1001,Data!$E$2:$E$1001,A14) -> 35386.378 | D14: =COUNTIFS(Data!$E$2:$E$1001,A14) -> 226 | E14: =IF(B14=0,0,C14/B14) -> 0.20930244
A15: South | B15: =SUMIFS(Data!$L$2:$L$1001,Data!$E$2:$E$1001,A15) -> 178929.03 | C15: =SUMIFS(Data!$N$2:$N$1001,Data!$E$2:$E$1001,A15) -> 39407.083 | D15: =COUNTIFS(Data!$E$2:$E$1001,A15) -> 267 | E15: =IF(B15=0,0,C15/B15) -> 0.22023862
A16: East | B16: =SUMIFS(Data!$L$2:$L$1001,Data!$E$2:$E$1001,A16) -> 170329.23 | C16: =SUMIFS(Data!$N$2:$N$1001,Data!$E$2:$E$1001,A16) -> 32090.349 | D16: =COUNTIFS(Data!$E$2:$E$1001,A16) -> 254 | E16: =IF(B16=0,0,C16/B16) -> 0.18840189
A17: West | B17: =SUMIFS(Data!$L$2:$L$1001,Data!$E$2:$E$1001,A17) -> 174483.21 | C17: =SUMIFS(Data!$N$2:$N$1001,Data!$E$2:$E$1001,A17) -> 39716.144 | D17: =COUNTIFS(Data!$E$2:$E$1001,A17) -> 253 | E17: =IF(B17=0,0,C17/B17) -> 0.22762157
A20: Sales by Category
A21: Category | B21: Sales | C21: Profit | D21: Orders | E21: Margin
A22: Electronics | B22: =SUMIFS(Data!$L$2:$L$1001,Data!$G$2:$G$1001,A22) -> 330663.06 | C22: =SUMIFS(Data!$N$2:$N$1001,Data!$G$2:$G$1001,A22) -> 37116.163 | D22: =COUNTIFS(Data!$G$2:$G$1001,A22) -> 268 | E22: =IF(B22=0,0,C22/B22) -> 0.11224768
A23: Furniture | B23: =SUMIFS(Data!$L$2:$L$1001,Data!$G$2:$G$1001,A23) -> 147942.93 | C23: =SUMIFS(Data!$N$2:$N$1001,Data!$G$2:$G$1001,A23) -> 38043.947 | D23: =COUNTIFS(Data!$G$2:$G$1001,A23) -> 140 | E23: =IF(B23=0,0,C23/B23) -> 0.25715286
A24: Clothing | B24: =SUMIFS(Data!$L$2:$L$1001,Data!$G$2:$G$1001,A24) -> 49082.554 | C24: =SUMIFS(Data!$N$2:$N$1001,Data!$G$2:$G$1001,A24) -> 21714.064 | D24: =COUNTIFS(Data!$G$2:$G$1001,A24) -> 246 | E24: =IF(B24=0,0,C24/B24) -> 0.44239883
A25: Home & Kitchen | B25: =SUMIFS(Data!$L$2:$L$1001,Data!$G$2:$G$1001,A25) -> 94428.272 | C25: =SUMIFS(Data!$N$2:$N$1001,Data!$G$2:$G$1001,A25) -> 28837.642 | D25: =COUNTIFS(Data!$G$2:$G$1001,A25) -> 211 | E25: =IF(B25=0,0,C25/B25) -> 0.30539203
A26: Sports | B26: =SUMIFS(Data!$L$2:$L$1001,Data!$G$2:$G$1001,A26) -> 70692.818 | C26: =SUMIFS(Data!$N$2:$N$1001,Data!$G$2:$G$1001,A26) -> 20888.137 | D26: =COUNTIFS(Data!$G$2:$G$1001,A26) -> 135 | E26: =IF(B26=0,0,C26/B26) -> 0.29547751
A29: Monthly Sales Trend
A30: Month | B30: Sales | C30: Profit | D30: Orders
A31: 45658 | B31: =SUMIFS(Data!$L$2:$L$1001,Data!$B$2:$B$1001,">="&A31,Data!$B$2:$B$1001,"<"&EDATE(A31,1)) -> 57653.931 | C31: =SUMIFS(Data!$N$2:$N$1001,Data!$B$2:$B$1001,">="&A31,Data!$B$2:$B$1001,"<"&EDATE(A31,1)) -> 13836.601 | D31: =COUNTIFS(Data!$B$2:$B$1001,">="&A31,Data!$B$2:$B$1001,"<"&EDATE(A31,1)) -> 76
A32: 45689 | B32: =SUMIFS(Data!$L$2:$L$1001,Data!$B$2:$B$1001,">="&A32,Data!$B$2:$B$1001,"<"&EDATE(A32,1)) -> 65058.561 | C32: =SUMIFS(Data!$N$2:$N$1001,Data!$B$2:$B$1001,">="&A32,Data!$B$2:$B$1001,"<"&EDATE(A32,1)) -> 11736.741 | D32: =COUNTIFS(Data!$B$2:$B$1001,">="&A32,Data!$B$2:$B$1001,"<"&EDATE(A32,1)) -> 86
A33: 45717 | B33: =SUMIFS(Data!$L$2:$L$1001,Data!$B$2:$B$1001,">="&A33,Data!$B$2:$B$1001,"<"&EDATE(A33,1)) -> 54263.727 | C33: =SUMIFS(Data!$N$2:$N$1001,Data!$B$2:$B$1001,">="&A33,Data!$B$2:$B$1001,"<"&EDATE(A33,1)) -> 10384.147 | D33: =COUNTIFS(Data!$B$2:$B$1001,">="&A33,Data!$B$2:$B$1001,"<"&EDATE(A33,1)) -> 73
A34: 45748 | B34: =SUMIFS(Data!$L$2:$L$1001,Data!$B$2:$B$1001,">="&A34,Data!$B$2:$B$1001,"<"&EDATE(A34,1)) -> 63909.561 | C34: =SUMIFS(Data!$N$2:$N$1001,Data!$B$2:$B$1001,">="&A34,Data!$B$2:$B$1001,"<"&EDATE(A34,1)) -> 13819.881 | D34: =COUNTIFS(Data!$B$2:$B$1001,">="&A34,Data!$B$2:$B$1001,"<"&EDATE(A34,1)) -> 86
A35: 45778 | B35: =SUMIFS(Data!$L$2:$L$1001,Data!$B$2:$B$1001,">="&A35,Data!$B$2:$B$1001,"<"&EDATE(A35,1)) -> 60650.416 | C35: =SUMIFS(Data!$N$2:$N$1001,Data!$B$2:$B$1001,">="&A35,Data!$B$2:$B$1001,"<"&EDATE(A35,1)) -> 12445.136 | D35: =COUNTIFS(Data!$B$2:$B$1001,">="&A35,Data!$B$2:$B$1001,"<"&EDATE(A35,1)) -> 105
A36: 45809 | B36: =SUMIFS(Data!$L$2:$L$1001,Data!$B$2:$B$1001,">="&A36,Data!$B$2:$B$1001,"<"&EDATE(A36,1)) -> 53418.729 | C36: =SUMIFS(Data!$N$2:$N$1001,Data!$B$2:$B$1001,">="&A36,Data!$B$2:$B$1001,"<"&EDATE(A36,1)) -> 14467.6 | D36: =COUNTIFS(Data!$B$2:$B$1001,">="&A36,Data!$B$2:$B$1001,"<"&EDATE(A36,1)) -> 77
A37: 45839 | B37: =SUMIFS(Data!$L$2:$L$1001,Data!$B$2:$B$1001,">="&A37,Data!$B$2:$B$1001,"<"&EDATE(A37,1)) -> 55141.332 | C37: =SUMIFS(Data!$N$2:$N$1001,Data!$B$2:$B$1001,">="&A37,Data!$B$2:$B$1001,"<"&EDATE(A37,1)) -> 10426.151 | D37: =COUNTIFS(Data!$B$2:$B$1001,">="&A37,Data!$B$2:$B$1001,"<"&EDATE(A37,1)) -> 72
A38: 45870 | B38: =SUMIFS(Data!$L$2:$L$1001,Data!$B$2:$B$1001,">="&A38,Data!$B$2:$B$1001,"<"&EDATE(A38,1)) -> 63671.493 | C38: =SUMIFS(Data!$N$2:$N$1001,Data!$B$2:$B$1001,">="&A38,Data!$B$2:$B$1001,"<"&EDATE(A38,1)) -> 14990.563 | D38: =COUNTIFS(Data!$B$2:$B$1001,">="&A38,Data!$B$2:$B$1001,"<"&EDATE(A38,1)) -> 95
A39: 45901 | B39: =SUMIFS(Data!$L$2:$L$1001,Data!$B$2:$B$1001,">="&A39,Data!$B$2:$B$1001,"<"&EDATE(A39,1)) -> 57260.532 | C39: =SUMIFS(Data!$N$2:$N$1001,Data!$B$2:$B$1001,">="&A39,Data!$B$2:$B$1001,"<"&EDATE(A39,1)) -> 8494.3015 | D39: =COUNTIFS(Data!$B$2:$B$1001,">="&A39,Data!$B$2:$B$1001,"<"&EDATE(A39,1)) -> 65
A40: 45931 | B40: =SUMIFS(Data!$L$2:$L$1001,Data!$B$2:$B$1001,">="&A40,Data!$B$2:$B$1001,"<"&EDATE(A40,1)) -> 59391.195 | C40: =SUMIFS(Data!$N$2:$N$1001,Data!$B$2:$B$1001,">="&A40,Data!$B$2:$B$1001,"<"&EDATE(A40,1)) -> 12760.105 | D40: =COUNTIFS(Data!$B$2:$B$1001,">="&A40,Data!$B$2:$B$1001,"<"&EDATE(A40,1)) -> 96
A41: 45962 | B41: =SUMIFS(Data!$L$2:$L$1001,Data!$B$2:$B$1001,">="&A41,Data!$B$2:$B$1001,"<"&EDATE(A41,1)) -> 50726.044 | C41: =SUMIFS(Data!$N$2:$N$1001,Data!$B$2:$B$1001,">="&A41,Data!$B$2:$B$1001,"<"&EDATE(A41,1)) -> 12120.754 | D41: =COUNTIFS(Data!$B$2:$B$1001,">="&A41,Data!$B$2:$B$1001,"<"&EDATE(A41,1)) -> 78
A42: 45992 | B42: =SUMIFS(Data!$L$2:$L$1001,Data!$B$2:$B$1001,">="&A42,Data!$B$2:$B$1001,"<"&EDATE(A42,1)) -> 51664.112 | C42: =SUMIFS(Data!$N$2:$N$1001,Data!$B$2:$B$1001,">="&A42,Data!$B$2:$B$1001,"<"&EDATE(A42,1)) -> 11117.972 | D42: =COUNTIFS(Data!$B$2:$B$1001,">="&A42,Data!$B$2:$B$1001,"<"&EDATE(A42,1)) -> 91
A44: Top Sales Reps
A45: Sales Rep | B45: Sales | C45: Profit | D45: Orders
A46: Aarav Sharma | B46: =SUMIFS(Data!$L$2:$L$1001,Data!$P$2:$P$1001,A46) -> 73411.412 | C46: =SUMIFS(Data!$N$2:$N$1001,Data!$P$2:$P$1001,A46) -> 16418.161 | D46: =COUNTIFS(Data!$P$2:$P$1001,A46) -> 112
A47: Priya Nair | B47: =SUMIFS(Data!$L$2:$L$1001,Data!$P$2:$P$1001,A47) -> 97597.534 | C47: =SUMIFS(Data!$N$2:$N$1001,Data!$P$2:$P$1001,A47) -> 18769.503 | D47: =COUNTIFS(Data!$P$2:$P$1001,A47) -> 140
A48: Rohan Mehta | B48: =SUMIFS(Data!$L$2:$L$1001,Data!$P$2:$P$1001,A48) -> 99153.062 | C48: =SUMIFS(Data!$N$2:$N$1001,Data!$P$2:$P$1001,A48) -> 21912.202 | D48: =COUNTIFS(Data!$P$2:$P$1001,A48) -> 128
...

Sheet Report Summary
A1: 2025 Retail Sales Analysis — Report Summary
A2: Report period | C2: January–December 2025
A3: Data note | C3: The Guide identifies these 1,000 retail orders as randomly generated practice data, not real company results.
A5: KEY METRICS
A6: Metric | B6: Result | C6: Meaning
A7: Total sales | B7: =Analysis!B4 -> 692809.63 | C7: Net sales after discounts.
A8: Total profit | B8: =Analysis!B5 -> 146599.95 | C8: Sales less quantity multiplied by unit cost.
A9: Profit margin | B9: =Analysis!B6 -> 0.21160207 | C9: Overall profit divided by sales.
A10: Orders | B10: =Analysis!B7 -> 1000 | C10: Order count for the year.
A11: Average order value | B11: =Analysis!B8 -> 692.80963 | C11: Total sales divided by orders.
A12: Average rating | B12: =Analysis!B9 -> 3.839 | C12: Average customer rating on a 1–5 scale.
A14: EXECUTIVE FINDINGS
A15: Finding | C15: What the analysis shows
A16: 1. Overall | C16: The 1,000 orders generated $692,810 in sales and $146,600 in profit, for a 21.2% overall margin. Average order value was $692.81 and average rating was 3.84/5.
A17: 2. Category | C17: Electronics was the largest category by sales at $330,663 (about 47.7% of total), but its margin was lowest at 11.2%. Clothing had the strongest category margin at 44.2%, on $49,083 of sales.
A18: 3. Region | C18: South led sales at $178,929. West delivered the highest regional profit ($39,716) and margin (22.8%); East had the lowest margin at 18.8%.
A19: 4. Monthly | C19: February was the strongest sales month ($65,059); November was the weakest ($50,726). August generated the highest monthly profit ($14,991), while September was lowest ($8,494).
A20: 5. Sales team | C20: Karan Patel led sales with $106,727. Rohan Mehta generated the highest profit at $21,912, showing that the sales leader and profit leader differ.
A22: RECOMMENDATIONS
A23: 1. Improve mix economics | C23: Review Electronics product mix, pricing, unit costs, and discounting before prioritizing further volume; focus on profitable growth. Test whether high-margin Clothing and Furniture products can grow without eroding their margins.
A24: 2. Investigate regional and seasonal gaps | C24: Examine East-region discount, cost, and category mix versus West; use the February sales and August profit peaks to inform promotions and inventory planning, then validate against future actual results.

Sheet work data
A1: Order ID | B1: Order Date | C1: Customer ID | D1: Segment | E1: Region | F1: State | G1: Category | H1: Product | I1: Quantity | J1: Unit Price | K1: Discount % | L1: Sales | M1: Unit Cost | N1: Profit | O1: Payment Method | P1: Sales Rep | Q1: Rating | R1: Profit Margin | S1: Order Size
A2: ORD-10001 | B2: 45658 | C2: CUST-0384 | D2: Small Business | E2: North | F2: Delhi | G2: Clothing | H2: Jeans | I2: 1 | J2: 84.05 | K2: 0 | L2: =I2*J2*(1-K2) -> 84.05 | M2: 37.26 | N2: =L2-I2*M2 -> 46.79 | O2: UPI | P2: Meera Reddy | Q2: 3 | R2: =IF(L2=0,0,N2/L2) -> 0.55669244 | S2: =IF(L2>=2000,"Large",IF(L2>=500,"Medium","Small")) -> Small
A3: ORD-10002 | B3: 45658 | C3: CUST-0222 | D3: Small Business | E3: West | F3: Gujarat | G3: Home & Kitchen | H3: Vacuum Cleaner | I3: 1 | J3: 381.08 | K3: 0 | L3: =I3*J3*(1-K3) -> 381.08 | M3: 247.67 | N3: =L3-I3*M3 -> 133.41 | O3: UPI | P3: Vikram Singh | Q3: 1 | R3: =IF(L3=0,0,N3/L3) -> 0.35008397 | S3: =IF(L3>=2000,"Large",IF(L3>=500,"Medium","Small")) -> Small
A4: ORD-10003 | B4: 45658 | C4: CUST-0241 | D4: Small Business | E4: East | F4: Bihar | G4: Electronics | H4: Smartwatch | I4: 1 | J4: 297.24 | K4: 0.1 | L4: =I4*J4*(1-K4) -> 267.516 | M4: 266.59 | N4: =L4-I4*M4 -> 0.926 | O4: Cash | P4: Vikram Singh | Q4: 3 | R4: =IF(L4=0,0,N4/L4) -> 0.0034614752 | S4: =IF(L4>=2000,"Large",IF(L4>=500,"Medium","Small")) -> Small
A5: ORD-10004 | B5: 45659 | C5: CUST-0083 | D5: Corporate | E5: West | F5: Gujarat | G5: Clothing | H5: Sneakers | I5: 2 | J5: 156.29 | K5: 0 | L5: =I5*J5*(1-K5) -> 312.58 | M5: 83.22 | N5: =L5-I5*M5 -> 146.14 | O5: Cash | P5: Meera Reddy | Q5: 3 | R5: =IF(L5=0,0,N5/L5) -> 0.46752831 | S5: =IF(L5>=2000,"Large",IF(L5>=500,"Medium","Small")) -> Small
A6: ORD-10005 | B6: 45659 | C6: CUST-0264 | D6: Consumer | E6: East | F6: West Bengal | G6: Sports | H6: Yoga Mat | I6: 10 | J6: 29.28 | K6: 0.05 | L6: =I6*J6*(1-K6) -> 278.16 | M6: 20.12 | N6: =L6-I6*M6 -> 76.96 | O6: Net Banking | P6: Meera Reddy | Q6: 4 | R6: =IF(L6=0,0,N6/L6) -> 0.27667529 | S6: =IF(L6>=2000,"Large",IF(L6>=500,"Medium","Small")) -> Small
A7: ORD-10006 | B7: 45659 | C7: CUST-0148 | D7: Corporate | E7: West | F7: Maharashtra | G7: Electronics | H7: Headphones | I7: 1 | J7: 198.11 | K7: 0.05 | L7: =I7*J7*(1-K7) -> 188.2045 | M7: 163.49 | N7: =L7-I7*M7 -> 24.7145 | O7: Cash | P7: Priya Nair | Q7: 1 | R7: =IF(L7=0,0,N7/L7) -> 0.13131726 | S7: =IF(L7>=2000,"Large",IF(L7>=500,"Medium","Small")) -> Small
A8: ORD-10007 | B8: 45659 | C8: CUST-0059 | D8: Corporate | E8: North | F8: Haryana | G8: Clothing | H8: Jeans | I8: 2 | J8: 71.14 | K8: 0 | L8: =I8*J8*(1-K8) -> 142.28 | M8: 40.71 | N8: =L8-I8*M8 -> 60.86 | O8: Credit Card | P8: Rohan Mehta | Q8: 4 | R8: =IF(L8=0,0,N8/L8) -> 0.4277481 | S8: =IF(L8>=2000,"Large",IF(L8>=500,"Medium","Small")) -> Small
A9: ORD-10008 | B9: 45660 | C9: CUST-0098 | D9: Small Business | E9: West | F9: Maharashtra | G9: Home & Kitchen | H9: Cookware Set | I9: 2 | J9: 127.25 | K9: 0 | L9: =I9*J9*(1-K9) -> 254.5 | M9: 83.16 | N9: =L9-I9*M9 -> 88.18 | O9: Net Banking | P9: Rohan Mehta | Q9: 5 | R9: =IF(L9=0,0,N9/L9) -> 0.3464833 | S9: =IF(L9>=2000,"Large",IF(L9>=500,"Medium","Small")) -> Small
A10: ORD-10009 | B10: 45661 | C10: CUST-0301 | D10: Small Business | E10: East | F10: West Bengal | G10: Furniture | H10: Sofa | I10: 1 | J10: 605.89 | K10: 0 | L10: =I10*J10*(1-K10) -> 605.89 | M10: 389.26 | N10: =L10-I10*M10 -> 216.63 | O10: Cash | P10: Rohan Mehta | Q10: 4 | R10: =IF(L10=0,0,N10/L10) -> 0.35754015 | S10: =IF(L10>=2000,"Large",IF(L10>=500,"Medium","Small")) -> Medium
A11: ORD-10010 | B11: 45661 | C11: CUST-0123 | D11: Small Business | E11: West | F11: Gujarat | G11: Clothing | H11: Jacket | I11: 5 | J11: 141.59 | K11: 0.2 | L11: =I11*J11*(1-K11) -> 566.36 | M11: 72.8 | N11: =L11-I11*M11 -> 202.36 | O11: Cash | P11: Sneha Iyer | Q11: 5 | R11: =IF(L11=0,0,N11/L11) -> 0.35729924 | S11: =IF(L11>=2000,"Large",IF(L11>=500,"Medium","Small")) -> Medium
A12: ORD-10011 | B12: 45661 | C12: CUST-0334 | D12: Consumer | E12: West | F12: Gujarat | G12: Clothing | H12: Jacket | I12: 10 | J12: 175.32 | K12: 0.1 | L12: =I12*J12*(1-K12) -> 1577.88 | M12: 83.05 | N12: =L12-I12*M12 -> 747.38 | O12: Cash | P12: Aarav Sharma | Q12: 3 | R12: =IF(L12=0,0,N12/L12) -> 0.47366086 | S12: =IF(L12>=2000,"Large",IF(L12>=500,"Medium","Small")) -> Medium
A13: ORD-10012 | B13: 45662 | C13: CUST-0370 | D13: Consumer | E13: West | F13: Maharashtra | G13: Sports | H13: Bicycle | I13: 2 | J13: 715.31 | K13: 0.05 | L13: =I13*J13*(1-K13) -> 1359.089 | M13: 411.42 | N13: =L13-I13*M13 -> 536.249 | O13: Cash | P13: Rohan Mehta | Q13: 2 | R13: =IF(L13=0,0,N13/L13) -> 0.39456504 | S13: =IF(L13>=2000,"Large",IF(L13>=500,"Medium","Small")) -> Medium
... A1001: ORD-11000 | B1001: 46022 | C1001: CUST-0140 | D1001: Corporate | E1001: East | F1001: West Bengal | G1001: Electronics | H1001: Headphones | I1001: 8 | J1001: 268.13 | K1001: 0.1 | L1001: =I1001*J1001*(1-K1001) -> 1930.536 | M1001: 224.31 | N1001: =L1001-I1001*M1001 -> 136.056 | O1001: Credit Card | P1001: Karan Patel | Q1001: 5 | R1001: =IF(L1001=0,0,N1001/L1001) -> 0.070475764 | S1001: =IF(L1001>=2000,"Large",IF(L1001>=500,"Medium","Small")) -> Medium

Sheet pivot table
A3: Row Labels | B3: Count of Order ID | C3: Sum of Sales | D3: Sum of Profit | F3: Row Labels | G3: Count of Order ID | H3: Sum of Profit | I3: Sum of Sales
A4: Aarav Sharma | B4: 112 | C4: 73411.412 | D4: 16418.161 | F4: 2025 | G4: 1000 | H4: 146599.95 | I4: 692809.63
A5: Ananya Das | B5: 108 | C5: 70757.18 | D5: 15585.4 | F5: Jan | G5: 76 | H5: 13836.601 | I5: 57653.931
A6: Karan Patel | B6: 138 | C6: 106727.46 | D6: 21688.877 | F6: Feb | G6: 86 | H6: 11736.741 | I6: 65058.561
A7: Meera Reddy | B7: 121 | C7: 82557.764 | D7: 19780.794 | F7: Mar | G7: 73 | H7: 10384.147 | I7: 54263.727
A8: Priya Nair | B8: 140 | C8: 97597.534 | D8: 18769.503 | F8: Apr | G8: 86 | H8: 13819.881 | I8: 63909.561
A9: Rohan Mehta | B9: 128 | C9: 99153.062 | D9: 21912.202 | F9: May | G9: 105 | H9: 12445.136 | I9: 60650.416
A10: Sneha Iyer | B10: 134 | C10: 83739.373 | D10: 15879.062 | F10: Jun | G10: 77 | H10: 14467.6 | I10: 53418.729
A11: Vikram Singh | B11: 119 | C11: 78865.852 | D11: 16565.953 | F11: Jul | G11: 72 | H11: 10426.151 | I11: 55141.332
A12: Grand Total | B12: 1000 | C12: 692809.63 | D12: 146599.95 | F12: Aug | G12: 95 | H12: 14990.563 | I12: 63671.493
F13: Sep | G13: 65 | H13: 8494.3015 | I13: 57260.532
F14: Oct | G14: 96 | H14: 12760.105 | I14: 59391.195
F15: Nov | G15: 78 | H15: 12120.754 | I15: 50726.044
F16: Dec | G16: 91 | H16: 11117.972 | I16: 51664.112
F17: Grand Total | G17: 1000 | H17: 146599.95 | I17: 692809.63
A18: Row Labels | B18: Sum of Quantity | C18: Count of Order ID | D18: Sum of Sales | E18: Sum of Profit
A19: Furniture | B19: 394 | C19: 140 | D19: 147942.93 | E19: 38043.947
A20: Clothing | B20: 690 | C20: 246 | D20: 49082.554 | E20: 21714.064
A21: Electronics | B21: 787 | C21: 268 | D21: 330663.06 | E21: 37116.163
A22: Home & Kitchen | B22: 676 | C22: 211 | D22: 94428.272 | E22: 28837.642
A23: Sports | B23: 407 | C23: 135 | D23: 70692.818 | E23: 20888.137
A24: Grand Total | B24: 2954 | C24: 1000 | D24: 692809.63 | E24: 146599.95
F26: Row Labels | G26: Sum of Profit | H26: Count of Order ID | I26: Sum of Sales
F27: East | G27: 32090.349 | H27: 254 | I27: 170329.23
F28: North | G28: 35386.378 | H28: 226 | I28: 169068.16
F29: South | G29: 39407.083 | H29: 267 | I29: 178929.03
A30: Row Labels | B30: Count of Order ID | C30: Sum of Profit | D30: Sum of Sales | F30: West | G30: 39716.144 | H30: 253 | I30: 174483.21
A31: Laptop | B31: 44 | C31: 11427.479 | D31: 108555.23 | F31: Grand Total | G31: 146599.95 | H31: 1000 | I31: 692809.63
A32: Bicycle | B32: 35 | C32: 14686.141 | D32: 50977.361
A33: Blender | B33: 53 | C33: 3140.7405 | D33: 10418.14
A34: Bookshelf | B34: 28 | C34: 3418.664 | D34: 13209.914
A35: Coffee Maker | B35: 52 | C35: 5025.1615 | D35: 16507.601
A36: Cookware Set | B36: 56 | C36: 8668.536 | D36: 29523.106
A37: Desk | B37: 39 | C37: 8579.608 | D37: 37812.628
A38: Dumbbell Set | B38: 29 | C38: 1441.213 | D38: 4770.013
A39: Headphones | B39: 60 | C39: 3619.823 | D39: 26087.843
A40: Jacket | B40: 58 | C40: 8406.279 | D40: 18609.129
A41: Jeans | B41: 58 | C41: 3948.4395 | D41: 9081.4495
A42: Office Chair | B42: 31 | C42: 4710.615 | D42: 18364.445
A43: Smartphone | B43: 48 | C43: 8535.027 | D43: 82166.047
...

Sheet PIVOT TABLE 1
A3: Row Labels | B3: Sum of Sales
A4: Laptop | B4: 108555.23
A5: Bicycle | B5: 50977.361
A6: Blender | B6: 10418.14
A7: Bookshelf | B7: 13209.914
A8: Coffee Maker | B8: 16507.601
A9: Cookware Set | B9: 29523.106
A10: Desk | B10: 37812.628
A11: Dumbbell Set | B11: 4770.013
A12: Headphones | B12: 26087.843
A13: Jacket | B13: 18609.129
A14: Jeans | B14: 9081.4495 | E14: Row Labels | F14: Sum of Sales | G14: Sum of Quantity
A15: Office Chair | B15: 18364.445 | E15: Cash | F15: 144704.26 | G15: 526
A16: Smartphone | B16: 82166.047 | E16: Credit Card | F16: 164123.58 | G16: 699
A17: Smartwatch | B17: 42373.091 | E17: Debit Card | F17: 142715.87 | G17: 610
A18: Sneakers | B18: 17456.034 | E18: Net Banking | F18: 150134.9 | G18: 600
A19: Sofa | B19: 78555.939 | E19: UPI | F19: 91131.015 | G19: 519
A20: Tablet | B20: 71480.853 | E20: Grand Total | F20: 692809.63 | G20: 2954
A21: Tennis Racket | B21: 11901.201
A22: T-Shirt | B22: 3935.9415
A23: Vacuum Cleaner | B23: 37979.424 | E23: Row Labels | F23: Sum of Sales
A24: Yoga Mat | B24: 3044.242 | E24: Bihar | F24: 60623.98
A25: Grand Total | B25: 692809.63 | E25: Delhi | F25: 63517.301
E26: Gujarat | F26: 48501.653
E27: Haryana | F27: 53695.371
E28: Karnataka | F28: 64580.199
E29: Kerala | F29: 59303.76
E30: Maharashtra | F30: 50107.03
E31: Odisha | F31: 46261.175
E32: Punjab | F32: 51855.485
E33: Rajasthan | F33: 75874.531
E34: Tamil Nadu | F34: 55045.074
E35: West Bengal | F35: 63444.074
E36: Grand Total | F36: 692809.63
